<?xml version="1.0" ?>
<robot name="mybot">
  <joint name="mybot__link_0_JOINT_0" type="revolute">
    <parent link="mybot__base_link"/>
    <child link="mybot__wheel_1"/>
    <origin rpy="0  0  0" xyz="-0.6  -0.55 -0.1"/>
    <axis xyz="0  1  0"/>
    <limit effort="-1.0" lower="-1.79769e+308" upper="1.79769e+308" velocity="-1.0"/>
  </joint>
  <joint name="mybot__link_0_JOINT_1" type="revolute">
    <parent link="mybot__base_link"/>
    <child link="mybot__wheel_2"/>
    <origin rpy="0  0  0" xyz="-0.6   0.55 -0.1"/>
    <axis xyz="0  1  0"/>
    <limit effort="-1.0" lower="-1.79769e+308" upper="1.79769e+308" velocity="-1.0"/>
  </joint>
  <joint name="mybot__link_0_JOINT_2" type="revolute">
    <parent link="mybot__base_link"/>
    <child link="mybot__wheel_3"/>
    <origin rpy="0  0  0" xyz="0.6   0.55 -0.1"/>
    <axis xyz="0  1  0"/>
    <limit effort="-1.0" lower="-1.79769e+308" upper="1.79769e+308" velocity="-1.0"/>
  </joint>
  <joint name="mybot__link_0_JOINT_3" type="revolute">
    <parent link="mybot__base_link"/>
    <child link="mybot__wheel_4"/>
    <origin rpy="0  0  0" xyz="0.6  -0.55 -0.1"/>
    <axis xyz="0  1  0"/>
    <limit effort="-1.0" lower="-1.79769e+308" upper="1.79769e+308" velocity="-1.0"/>
  </joint>
  <link name="mybot__base_link">
    <inertial>
      <mass value="1.36848"/>
      <origin rpy="0  0  0" xyz="0  0  0"/>
      <inertia ixx="0.168113" ixy="0" ixz="0" iyy="0.504485" iyz="0" izz="0.564452"/>
    </inertial>
    <collision name="mybot__collision">
      <origin rpy="-0.00318  0       0" xyz="0   0   0.6"/>
      <geometry>
        <box size="1.98736 1 0.688594"/>
      </geometry>
    </collision>
    <visual name="mybot__visual">
      <origin rpy="3.14  0    0" xyz="0   0   0.6"/>
      <geometry>
        <mesh filename="package://mybot_description/meshes/potato.dae" scale="1.0 1.0 1.0"/>
      </geometry>
    </visual>
  </link>
  <link name="mybot__wheel_1">
    <inertial>
      <mass value="0.0862894"/>
      <origin rpy="0  0  0" xyz="0  0  0"/>
      <inertia ixx="0.00244153" ixy="0" ixz="0" iyy="0.00244153" iyz="0" izz="0.00416484"/>
    </inertial>
    <collision name="mybot__collision">
      <origin rpy="1.57  0    0" xyz="0  0  0"/>
      <geometry>
        <cylinder length="0.2" radius="0.3"/>
      </geometry>
    </collision>
    <visual name="mybot__visual">
      <origin rpy="0  0  0" xyz="0  0  0"/>
      <geometry>
        <mesh filename="package://mybot_description/meshes/wheel.dae" scale="1.5 1.5 1.5"/>
      </geometry>
    </visual>
  </link>
  <link name="mybot__wheel_2">
    <inertial>
      <mass value="0.0862894"/>
      <origin rpy="0  0  0" xyz="0  0  0"/>
      <inertia ixx="0.00244153" ixy="0" ixz="0" iyy="0.00244153" iyz="0" izz="0.00416484"/>
    </inertial>
    <collision name="mybot__collision">
      <origin rpy="1.57  0    0" xyz="0  0  0"/>
      <geometry>
        <cylinder length="0.2" radius="0.3"/>
      </geometry>
    </collision>
    <visual name="mybot__visual">
      <origin rpy="0  0  0" xyz="0  0  0"/>
      <geometry>
        <mesh filename="package://mybot_description/meshes/wheel.dae" scale="1.5 1.5 1.5"/>
      </geometry>
    </visual>
  </link>
  <link name="mybot__wheel_3">
    <inertial>
      <mass value="0.0862894"/>
      <origin rpy="0  0  0" xyz="0  0  0"/>
      <inertia ixx="0.00244153" ixy="0" ixz="0" iyy="0.00244153" iyz="0" izz="0.00416484"/>
    </inertial>
    <collision name="mybot__collision">
      <origin rpy="1.57  0    0" xyz="0  0  0"/>
      <geometry>
        <cylinder length="0.2" radius="0.3"/>
      </geometry>
    </collision>
    <visual name="mybot__visual">
      <origin rpy="0  0  0" xyz="0  0  0"/>
      <geometry>
        <mesh filename="package://mybot_description/meshes/wheel.dae" scale="1.5 1.5 1.5"/>
      </geometry>
    </visual>
  </link>
  <link name="mybot__wheel_4">
    <inertial>
      <mass value="0.0862894"/>
      <origin rpy="0  0  0" xyz="0  0  0"/>
      <inertia ixx="0.00244153" ixy="0" ixz="0" iyy="0.00244153" iyz="0" izz="0.00416484"/>
    </inertial>
    <collision name="mybot__collision">
      <origin rpy="1.57  0    0" xyz="0  0  0"/>
      <geometry>
        <cylinder length="0.223471" radius="0.310699"/>
      </geometry>
    </collision>
    <visual name="mybot__visual">
      <origin rpy="0  0  0" xyz="0  0  0"/>
      <geometry>
        <mesh filename="package://mybot_description/meshes/wheel.dae" scale="1.5 1.5 1.5"/>
      </geometry>
    </visual>
  </link>
</robot>
